<?xml version="1.0"?>
<robot name="nine_link_arm">
    <!-- Base Link -->
    <link name="base_link">
        <visual>
            <geometry>
                <cylinder length="0.1" radius="0.2"/>
            </geometry>
        </visual>
    </link>

    <!-- Link 1 -->
    <link name="link1">
        <visual>
            <geometry>
                <box size="0.5 0.1 0.1"/>
            </geometry>
            <origin xyz="0.25 0 0" rpy="0 0 0"/>
        </visual>
    </link>

    <!-- Joint 1: Base to Link 1 -->
    <joint name="joint1" type="revolute">
        <parent link="base_link"/>
        <child link="link1"/>
        <origin xyz="0 0 0" rpy="0 0 0"/>
        <axis xyz="0 0 1"/>
        <limit lower="-3.14" upper="3.14" effort="100" velocity="1"/>
        <mdh a="1.57" alpha="0" d="1" theta_offset="0"/>
    </joint>

    <!-- Link 2 -->
    <link name="link2">
        <visual>
            <geometry>
                <box size="0.5 0.1 0.1"/>
            </geometry>
            <origin xyz="0.25 0 0" rpy="0 0 0"/>
        </visual>
    </link>

    <!-- Joint 2: Link 1 to Link 2 -->
    <joint name="joint2" type="revolute">
        <parent link="link1"/>
        <child link="link2"/>
        <origin xyz="0.5 0 0" rpy="0 0 0"/>
        <axis xyz="0 0 1"/>
        <limit lower="-3.14" upper="3.14" effort="100" velocity="1"/>
        <mdh a="0.47" alpha="1.80" d="0.03" theta_offset="-0.22"/>
    </joint>

    <!-- Link 3 -->
    <link name="link3">
        <visual>
            <geometry>
                <box size="0.5 0.1 0.1"/>
            </geometry>
            <origin xyz="0.25 0 0" rpy="0 0 0"/>
        </visual>
    </link>

    <!-- Joint 3: Link 2 to Link 3 -->
    <joint name="joint3" type="revolute">
        <parent link="link2"/>
        <child link="link3"/>
        <origin xyz="0.5 0 0" rpy="0 0 0"/>
        <axis xyz="0 0 1"/>
        <limit lower="-3.14" upper="3.14" effort="100" velocity="1"/>
        <mdh a="0.62" alpha="1.12" d="0.11" theta_offset="0.31"/>
    </joint>

    <!-- Link 4 -->
    <link name="link4">
        <visual>
            <geometry>
                <box size="0.5 0.1 0.1"/>
            </geometry>
            <origin xyz="0.25 0 0" rpy="0 0 0"/>
        </visual>
    </link>

    <!-- Joint 4: Link 3 to Link 4 -->
    <joint name="joint4" type="revolute">
        <parent link="link3"/>
        <child link="link4"/>
        <origin xyz="0.5 0 0" rpy="0 0 0"/>
        <axis xyz="0 0 1"/>
        <limit lower="-3.14" upper="3.14" effort="100" velocity="1"/>
        <mdh a="0.39" alpha="1.67" d="0.06" theta_offset="-0.41"/>
    </joint>

    <!-- Link 5 -->
    <link name="link5">
        <visual>
            <geometry>
                <box size="0.5 0.1 0.1"/>
            </geometry>
            <origin xyz="0.25 0 0" rpy="0 0 0"/>
        </visual>
    </link>

    <!-- Joint 5: Link 4 to Link 5 -->
    <joint name="joint5" type="revolute">
        <parent link="link4"/>
        <child link="link5"/>
        <origin xyz="0.5 0 0" rpy="0 0 0"/>
        <axis xyz="0 0 1"/>
        <limit lower="-3.14" upper="3.14" effort="100" velocity="1"/>
        <mdh a="0.53" alpha="1.44" d="0.09" theta_offset="0.27"/>
    </joint>

    <!-- Link 6 -->
    <link name="link6">
        <visual>
            <geometry>
                <box size="0.5 0.1 0.1"/>
            </geometry>
            <origin xyz="0.25 0 0" rpy="0 0 0"/>
        </visual>
    </link>

    <!-- Joint 6: Link 5 to Link 6 -->
    <joint name="joint6" type="revolute">
        <parent link="link5"/>
        <child link="link6"/>
        <origin xyz="0.5 0 0" rpy="0 0 0"/>
        <axis xyz="0 0 1"/>
        <limit lower="-3.14" upper="3.14" effort="100" velocity="1"/>
        <mdh a="0.41" alpha="1.95" d="0.02" theta_offset="-0.19"/>
    </joint>

    <!-- Link 7 -->
    <link name="link7">
        <visual>
            <geometry>
                <box size="0.5 0.1 0.1"/>
            </geometry>
            <origin xyz="0.25 0 0" rpy="0 0 0"/>
        </visual>
    </link>

    <!-- Joint 7: Link 6 to Link 7 -->
    <joint name="joint7" type="revolute">
        <parent link="link6"/>
        <child link="link7"/>
        <origin xyz="0.5 0 0" rpy="0 0 0"/>
        <axis xyz="0 0 1"/>
        <limit lower="-3.14" upper="3.14" effort="100" velocity="1"/>
        <mdh a="0.58" alpha="1.21" d="0.13" theta_offset="0.09"/>
    </joint>

    <!-- Link 8 -->
    <link name="link8">
        <visual>
            <geometry>
                <box size="0.5 0.1 0.1"/>
            </geometry>
            <origin xyz="0.25 0 0" rpy="0 0 0"/>
        </visual>
    </link>

    <!-- Joint 8: Link 7 to Link 8 -->
    <joint name="joint8" type="revolute">
        <parent link="link7"/>
        <child link="link8"/>
        <origin xyz="0.5 0 0" rpy="0 0 0"/>
        <axis xyz="0 0 1"/>
        <limit lower="-3.14" upper="3.14" effort="100" velocity="1"/>
        <mdh a="0.36" alpha="1.78" d="0.05" theta_offset="-0.33"/>
    </joint>

    <!-- Link 9 -->
    <link name="link9">
        <visual>
            <geometry>
                <box size="0.5 0.1 0.1"/>
            </geometry>
            <origin xyz="0.25 0 0" rpy="0 0 0"/>
        </visual>
    </link>

    <!-- Joint 9: Link 8 to Link 9 -->
    <joint name="joint9" type="revolute">
        <parent link="link8"/>
        <child link="link9"/>
        <origin xyz="0.5 0 0" rpy="0 0 0"/>
        <axis xyz="0 0 1"/>
        <limit lower="-3.14" upper="3.14" effort="100" velocity="1"/>
        <mdh a="0.49" alpha="1.39" d="0.07" theta_offset="0.21"/>
    </joint>

</robot>
